Workbook

Sheet Transactions
A2: Transactions | B2: Month | N2: Annual Amount
B3: January | C3: February | D3: March | E3: April | F3: May | G3: June | H3: July | I3: August | J3: September | K3: October | L3: November | M3: December
A4: SALES
A5: Cash sales | N5: =SUM(B5:M5) -> 0
A6: Credit sales | N6: =SUM(B6:M6) -> 0
A7: Sales of the month | B7: =B5+B6 -> 0 | C7: =C5+C6 -> 0 | D7: =D5+D6 -> 0 | E7: =E5+E6 -> 0 | F7: =F5+F6 -> 0 | G7: =G5+G6 -> 0 | H7: =H5+H6 -> 0 | I7: =I5+I6 -> 0 | ... M7: =M5+M6 -> 0 | N7: =SUM(B7:M7) -> 0
A9: PURCHASES
A10: Cash purchases | N10: =SUM(B10:M10) -> 0
A11: Credit purchases | C11: =Transactions!C7+Transactions!C36+Transactions!C43+(Transactions!C7-Transactions!C46) -> 0 | D11: =Transactions!D7+Transactions!D36+Transactions!D43+(Transactions!D7-Transactions!D46) -> 0 | E11: =Transactions!E7+Transactions!E36+Transactions!E43+(Transactions!E7-Transactions!E46) -> 0 | F11: =Transactions!F7+Transactions!F36+Transactions!F43+(Transactions!F7-Transactions!F46) -> 0 | G11: =Transactions!G7+Transactions!G36+Transactions!G43+(Transactions!G7-Transactions!G46) -> 0 | H11: =Transactions!H7+Transactions!H36+Transactions!H43+(Transactions!H7-Transactions!H46) -> 0 | I11: =Transactions!I7+Transactions!I36+Transactions!I43+(Transactions!I7-Transactions!I46) -> 0 | J11: =Transactions!J7+Transactions!J36+Transactions!J43+(Transactions!J7-Transactions!J46) -> 0 | ... M11: =Transactions!M7+Transactions!M36+Transactions!M43+(Transactions!M7-Transactions!M46) -> 0 | N11: =SUM(B11:M11) -> 0
A12: Purchase of the month | B12: =B10+B11 -> 0 | C12: =C10+C11 -> 0 | D12: =D10+D11 -> 0 | E12: =E10+E11 -> 0 | F12: =F10+F11 -> 0 | G12: =G10+G11 -> 0 | H12: =H10+H11 -> 0 | I12: =I10+I11 -> 0 | ... M12: =M10+M11 -> 0 | N12: =SUM(B12:M12) -> 0
A14: OPERATING EXPENSES
A15: Salaries | N15: =SUM(B15:M15) -> 0
A16: Travel costs | N16: =SUM(B16:M16) -> 0
A17: Rent | N17: =SUM(B17:M17) -> 0
A18: Insurance | N18: =SUM(B18:M18) -> 0
A19: Repairs and maintenance | N19: =SUM(B19:M19) -> 0
A20: Office supplies | N20: =SUM(B20:M20) -> 0
A21: Advertising and marketing | N21: =SUM(B21:M21) -> 0
A22: Electricity | N22: =SUM(B22:M22) -> 0
A23: Water | N23: =SUM(B23:M23) -> 0
A24: Phone and Internet | N24: =SUM(B24:M24) -> 0
A25: Fuel | N25: =SUM(B25:M25) -> 0
A26: Municipal Fees | N26: =SUM(B26:B26) -> 0
A27: Other Operating Expenses | N27: =SUM(B27:M27) -> 0
A28: Total Operating Expenses | B28: =SUM(B15:B27) -> 0 | C28: =SUM(C15:C27) -> 0 | D28: =SUM(D15:D27) -> 0 | E28: =SUM(E15:E27) -> 0 | F28: =SUM(F15:F27) -> 0 | G28: =SUM(G15:G27) -> 0 | H28: =SUM(H15:H27) -> 0 | I28: =SUM(I15:I27) -> 0 | ... M28: =SUM(M15:M27) -> 0 | N28: =SUM(B28:M28) -> 0
A30: FINANCIAL EXPENSES
A31: Interest Paid | N31: =SUM(B31:M31) -> 0
A33: CASH AND BANKS
A34: How much cash do you manage monthly? | N34: =SUM(B34:M34) -> 0
A35: Amount in bank current accounts | N35: =SUM(B35:M35) -> 0
A36: Total Cash | B36: =B34+B35 -> 0 | C36: =C34+C35 -> 0 | D36: =D34+D35 -> 0 | E36: =E34+E35 -> 0 | F36: =F34+F35 -> 0 | G36: =G34+G35 -> 0 | H36: =H34+H35 -> 0 | I36: =I34+I35 -> 0 | ... M36: =M34+M35 -> 0 | N36: =SUM(B36:M36) -> 0
A38: Amounts in deposit accounts > 1 year | N38: =SUM(B38:M38) -> 0
A40: ACCOUNTS RECIEVABLE
A41: Credit Sales from Customers | B41: =B7-B5 -> 0 | C41: =C7-C5 -> 0 | D41: =D7-D5 -> 0 | E41: =E7-E5 -> 0 | F41: =F7-F5 -> 0 | G41: =G7-G5 -> 0 | H41: =H7-H5 -> 0 | I41: =I7-I5 -> 0 | ... M41: =M7-M5 -> 0 | N41: =SUM(B41:M41) -> 0
A42: Other Receivables | N42: =SUM(B42:M42) -> 0
A43: Total Accounts Receivable | B43: =B41+B42 -> 0 | C43: =C41+C42 -> 0 | D43: =D41+D42 -> 0 | E43: =E41+E42 -> 0 | F43: =F41+F42 -> 0 | G43: =G41+G42 -> 0 | H43: =H41+H42 -> 0 | I43: =I41+I42 -> 0 | ... M43: =M41+M42 -> 0 | N43: =SUM(B43:M43) -> 0
A45: INVENTORY
A46: Inventory of goods | N46: =SUM(B46:M46) -> 0
A48: LIABILITIES
A49: Bank Loans < 12 months | N49: =SUM(B49:M49) -> 0
...

Sheet FInancial Statements
A2: Categorisation | B2: Month | N2: Annual Amount
B3: January | C3: February | D3: March | E3: April | F3: May | G3: June | H3: July | I3: August | J3: September | K3: October | L3: November | M3: December
A4: Income Statement - summary
A5: Revenue | B5: =Transactions!B7 -> 0 | C5: =Transactions!C7 -> 0 | D5: =Transactions!D7 -> 0 | E5: =Transactions!E7 -> 0 | F5: =Transactions!F7 -> 0 | G5: =Transactions!G7 -> 0 | H5: =Transactions!H7 -> 0 | I5: =Transactions!I7 -> 0 | ... M5: =Transactions!M7 -> 0 | N5: =SUM(B5:M5) -> 0
A6: Less
A7: Expenses | B7: =Transactions!B12+Transactions!B28+Transactions!B31 -> 0 | C7: =Transactions!C12+Transactions!C28+Transactions!C31 -> 0 | D7: =Transactions!D12+Transactions!D28+Transactions!D31 -> 0 | E7: =Transactions!E12+Transactions!E28+Transactions!E31 -> 0 | F7: =Transactions!F12+Transactions!F28+Transactions!F31 -> 0 | G7: =Transactions!G12+Transactions!G28+Transactions!G31 -> 0 | H7: =Transactions!H12+Transactions!H28+Transactions!H31 -> 0 | I7: =Transactions!I12+Transactions!I28+Transactions!I31 -> 0 | ... M7: =Transactions!M12+Transactions!M28+Transactions!M31 -> 0 | N7: =SUM(B7:M7) -> 0
A8: Net income | B8: =B5-B7 -> 0 | C8: =C5-C7 -> 0 | D8: =D5-D7 -> 0 | E8: =E5-E7 -> 0 | F8: =F5-F7 -> 0 | G8: =G5-G7 -> 0 | H8: =H5-H7 -> 0 | I8: =I5-I7 -> 0 | ... M8: =M5-M7 -> 0 | N8: =SUM(B8:M8) -> 0
A10: Balance Sheet - summary
A11: Assets
A12: Current Assets | B12: =Transactions!B34+Transactions!B35+Transactions!B41+Transactions!B42+(Transactions!B7-Transactions!B46) -> 0 | C12: =Transactions!C34+Transactions!C35+Transactions!C41+Transactions!C42+(Transactions!C7-Transactions!C46) -> 0 | D12: =Transactions!D34+Transactions!D35+Transactions!D41+Transactions!D42+(Transactions!D7-Transactions!D46) -> 0 | E12: =Transactions!E34+Transactions!E35+Transactions!E41+Transactions!E42+(Transactions!E7-Transactions!E46) -> 0 | F12: =Transactions!F34+Transactions!F35+Transactions!F41+Transactions!F42+(Transactions!F7-Transactions!F46) -> 0 | G12: =Transactions!G34+Transactions!G35+Transactions!G41+Transactions!G42+(Transactions!G7-Transactions!G46) -> 0 | H12: =Transactions!H34+Transactions!H35+Transactions!H41+Transactions!H42+(Transactions!H7-Transactions!H46) -> 0 | I12: =Transactions!I34+Transactions!I35+Transactions!I41+Transactions!I42+(Transactions!I7-Transactions!I46) -> 0 | ... M12: =Transactions!M34+Transactions!M35+Transactions!M41+Transactions!M42+(Transactions!M7-Transactions!M46) -> 0 | N12: =SUM(B12:M12) -> 0
A13: Fixed Assets (non-current assets) | B13: =Transactions!B71 -> 0 | C13: =Transactions!C65+Transactions!C68+Transactions!C69 -> 0 | D13: =Transactions!D65+Transactions!D68+Transactions!D69 -> 0 | E13: =Transactions!E65+Transactions!E68+Transactions!E69 -> 0 | F13: =Transactions!F65+Transactions!F68+Transactions!F69 -> 0 | G13: =Transactions!G65+Transactions!G68+Transactions!G69 -> 0 | H13: =Transactions!H65+Transactions!H68+Transactions!H69 -> 0 | I13: =Transactions!I65+Transactions!I68+Transactions!I69 -> 0 | J13: =Transactions!J65+Transactions!J68+Transactions!J69 -> 0 | ... M13: =Transactions!M65+Transactions!M68+Transactions!M69 -> 0 | N13: =SUM(B13:M13) -> 0
A14: Total Assets | B14: =SUM(B12:B13) -> 0 | C14: =SUM(C12:C13) -> 0 | D14: =SUM(D12:D13) -> 0 | E14: =SUM(E12:E13) -> 0 | F14: =SUM(F12:F13) -> 0 | G14: =SUM(G12:G13) -> 0 | H14: =SUM(H12:H13) -> 0 | I14: =SUM(I12:I13) -> 0 | ... M14: =SUM(M12:M13) -> 0 | N14: =SUM(B14:M14) -> 0
A16: Liability and Equity
A17: Current Liability | B17: =Transactions!B58 -> 0 | C17: =Transactions!C58 -> 0 | D17: =Transactions!D58 -> 0 | E17: =Transactions!E58 -> 0 | F17: =Transactions!F58 -> 0 | G17: =Transactions!G58 -> 0 | H17: =Transactions!H58 -> 0 | I17: =Transactions!I58 -> 0 | ... M17: =Transactions!M58 -> 0 | N17: =SUM(B17:M17) -> 0
A18: Long Term Liability (non-current liability) | B18: =Transactions!B62 -> 0 | C18: =Transactions!C62 -> 0 | D18: =Transactions!D62 -> 0 | E18: =Transactions!E62 -> 0 | F18: =Transactions!F62 -> 0 | G18: =Transactions!G62 -> 0 | H18: =Transactions!H62 -> 0 | I18: =Transactions!I62 -> 0 | ... M18: =Transactions!M62 -> 0 | N18: =SUM(B18:M18) -> 0
A19: Equity | B19: =B14-B17-B18 -> 0 | C19: =C14-C17-C18 -> 0 | D19: =D14-D17-D18 -> 0 | E19: =E14-E17-E18 -> 0 | F19: =F14-F17-F18 -> 0 | G19: =G14-G17-G18 -> 0 | H19: =H14-H17-H18 -> 0 | I19: =I14-I17-I18 -> 0 | ... M19: =M14-M17-M18 -> 0 | N19: =SUM(B19:M19) -> 0
A20: Total Liability and Equity | B20: =SUM(B17:B19) -> 0 | C20: =SUM(C17:C19) -> 0 | D20: =SUM(D17:D19) -> 0 | E20: =SUM(E17:E19) -> 0 | F20: =SUM(F17:F19) -> 0 | G20: =SUM(G17:G19) -> 0 | H20: =SUM(H17:H19) -> 0 | I20: =SUM(I17:I19) -> 0 | ... M20: =SUM(M17:M19) -> 0 | N20: =SUM(B20:M20) -> 0
A22: Break-even | B22: =Transactions!B28/(1-(Transactions!B12/Transactions!B7)) -> #DIV/0! | C22: =Transactions!C28/(1-(Transactions!C12/Transactions!C7)) -> #DIV/0! | D22: =Transactions!D28/(1-(Transactions!D12/Transactions!D7)) -> #DIV/0! | E22: =Transactions!E28/(1-(Transactions!E12/Transactions!E7)) -> #DIV/0! | F22: =Transactions!F28/(1-(Transactions!F12/Transactions!F7)) -> #DIV/0! | G22: =Transactions!G28/(1-(Transactions!G12/Transactions!G7)) -> #DIV/0! | H22: =Transactions!H28/(1-(Transactions!H12/Transactions!H7)) -> #DIV/0! | I22: =Transactions!I28/(1-(Transactions!I12/Transactions!I7)) -> #DIV/0! | ... N22: =Transactions!N28/(1-(Transactions!N12/Transactions!N7)) -> #DIV/0!
A24: Cash flow
A25: Cash Flow | B25: =B8+Transactions!B31+Transactions!B55-Transactions!B43 -> 0 | C25: =C8+Transactions!C31+Transactions!C55-Transactions!C43 -> 0 | D25: =D8+Transactions!D31+Transactions!D55-Transactions!D43 -> 0 | E25: =E8+Transactions!E31+Transactions!E55-Transactions!E43 -> 0 | F25: =F8+Transactions!F31+Transactions!F55-Transactions!F43 -> 0 | G25: =G8+Transactions!G31+Transactions!G55-Transactions!G43 -> 0 | H25: =H8+Transactions!H31+Transactions!H55-Transactions!H43 -> 0 | I25: =I8+Transactions!I31+Transactions!I55-Transactions!I43 -> 0 | ... M25: =M8+Transactions!M31+Transactions!M55-Transactions!M43 -> 0 | N25: =SUM(B25:M25) -> 0
A27: Income Statement - detailed
A28: Sales | B28: =Transactions!B7 -> 0 | C28: =Transactions!C7 -> 0 | D28: =Transactions!D7 -> 0 | E28: =Transactions!E7 -> 0 | F28: =Transactions!F7 -> 0 | G28: =Transactions!G7 -> 0 | H28: =Transactions!H7 -> 0 | I28: =Transactions!I7 -> 0 | ... M28: =Transactions!M7 -> 0 | N28: =SUM(B28:M28) -> 0
A29: Less:
A30: Purchases | B30: =Transactions!B12 -> 0 | C30: =Transactions!C12 -> 0 | D30: =Transactions!D12 -> 0 | E30: =Transactions!E12 -> 0 | F30: =Transactions!F12 -> 0 | G30: =Transactions!G12 -> 0 | H30: =Transactions!H12 -> 0 | I30: =Transactions!I12 -> 0 | ... M30: =Transactions!M12 -> 0 | N30: =SUM(B30:M30) -> 0
A31: Gross Profit | B31: =B28-B30 -> 0 | C31: =C28-C30 -> 0 | D31: =D28-D30 -> 0 | E31: =E28-E30 -> 0 | F31: =F28-F30 -> 0 | G31: =G28-G30 -> 0 | H31: =H28-H30 -> 0 | I31: =I28-I30 -> 0 | ... M31: =M28-M30 -> 0 | N31: =SUM(B31:M31) -> 0
A32: Less:
A33: Operating expenses and Financial Expenses | B33: =Transactions!B28+Transactions!B31 -> 0 | C33: =Transactions!C28+Transactions!C31 -> 0 | D33: =Transactions!D28+Transactions!D31 -> 0 | E33: =Transactions!E28+Transactions!E31 -> 0 | F33: =Transactions!F28+Transactions!F31 -> 0 | G33: =Transactions!G28+Transactions!G31 -> 0 | H33: =Transactions!H28+Transactions!H31 -> 0 | I33: =Transactions!I28+Transactions!I31 -> 0 | ... M33: =Transactions!M28+Transactions!M31 -> 0 | N33: =SUM(B33:M33) -> 0
A34: Profit before tax | B34: =B31-B33 -> 0 | C34: =C31-C33 -> 0 | D34: =D31-D33 -> 0 | E34: =E31-E33 -> 0 | F34: =F31-F33 -> 0 | G34: =G31-G33 -> 0 | H34: =H31-H33 -> 0 | I34: =I31-I33 -> 0 | ... M34: =M31-M33 -> 0 | N34: =SUM(B34:M34) -> 0
A35: Less:
A36: Tax Expenses | B36: 0 | C36: 0 | D36: 0 | E36: 0 | F36: 0 | G36: 0 | H36: 0 | I36: 0 | J36: 0 | K36: 0 | L36: 0 | M36: 0 | N36: =SUM(B36:M36) -> 0
A37: Net Income | B37: =B34-B36 -> 0 | C37: =C34-C36 -> 0 | D37: =D34-D36 -> 0 | E37: =E34-E36 -> 0 | F37: =F34-F36 -> 0 | G37: =G34-G36 -> 0 | H37: =H34-H36 -> 0 | I37: =I34-I36 -> 0 | ... M37: =M34-M36 -> 0 | N37: =SUM(B37:M37) -> 0
A39: Balance Sheet - detailed
A40: A. Current Assets
A41: Total Cash | B41: =Transactions!B36+B25 -> 0 | C41: =Transactions!C36+C25 -> 0 | D41: =Transactions!D36+D25 -> 0 | E41: =Transactions!E36+E25 -> 0 | F41: =Transactions!F36+F25 -> 0 | G41: =Transactions!G36+G25 -> 0 | H41: =Transactions!H36+H25 -> 0 | I41: =Transactions!I36+I25 -> 0 | ... M41: =Transactions!M36+M25 -> 0 | N41: =SUM(B41:M41) -> 0
A42: Accounts Receivable | B42: =Transactions!B43 -> 0 | C42: =Transactions!C43 -> 0 | D42: =Transactions!D43 -> 0 | E42: =Transactions!E43 -> 0 | F42: =Transactions!F43 -> 0 | G42: =Transactions!G43 -> 0 | H42: =Transactions!H43 -> 0 | I42: =Transactions!I43 -> 0 | ... M42: =Transactions!M43 -> 0 | N42: =SUM(B42:M42) -> 0
A43: Inventory | B43: =Transactions!B46 -> 0 | N43: =SUM(B43:M43) -> 0
A44: Total Current Assets | B44: =SUM(B41:B43) -> 0 | C44: =SUM(C41:C43) -> 0 | D44: =SUM(D41:D43) -> 0 | E44: =SUM(E41:E43) -> 0 | F44: =SUM(F41:F43) -> 0 | G44: =SUM(G41:G43) -> 0 | H44: =SUM(H41:H43) -> 0 | I44: =SUM(I41:I43) -> 0 | ... M44: =SUM(M41:M43) -> 0 | N44: =SUM(B44:M44) -> 0
A46: B. Fixed Term Assets
A47: Furniture, Machinery and Equipment | B47: =Transactions!B65+Transactions!B66+Transactions!B67 -> 0 | C47: =Transactions!C65+Transactions!C66+Transactions!C67 -> 0 | D47: =Transactions!D65+Transactions!D66+Transactions!D67 -> 0 | E47: =Transactions!E65+Transactions!E66+Transactions!E67 -> 0 | F47: =Transactions!F65+Transactions!F66+Transactions!F67 -> 0 | G47: =Transactions!G65+Transactions!G66+Transactions!G67 -> 0 | H47: =Transactions!H65+Transactions!H66+Transactions!H67 -> 0 | I47: =Transactions!I65+Transactions!I66+Transactions!I67 -> 0 | ... M47: =Transactions!M65+Transactions!M66+Transactions!M67 -> 0 | N47: =SUM(B47:M47) -> 0
A48: Vehicles | B48: =Transactions!B68 -> 0 | C48: =Transactions!C68 -> 0 | D48: =Transactions!D68 -> 0 | E48: =Transactions!E68 -> 0 | F48: =Transactions!F68 -> 0 | G48: =Transactions!G68 -> 0 | H48: =Transactions!H68 -> 0 | I48: =Transactions!I68 -> 0 | ... M48: =Transactions!M68 -> 0 | N48: =SUM(B48:M48) -> 0
...
